Traceback (most recent call last):
  File "/home/larsm/.cache/pypoetry/virtualenvs/digital-tekstanalyse-kDjkoATB-py3.10/lib/python3.10/site-packages/jupyter_cache/executors/utils.py", line 58, in single_nb_execution
    executenb(
  File "/home/larsm/.cache/pypoetry/virtualenvs/digital-tekstanalyse-kDjkoATB-py3.10/lib/python3.10/site-packages/nbclient/client.py", line 1314, in execute
    return NotebookClient(nb=nb, resources=resources, km=km, **kwargs).execute()
  File "/home/larsm/.cache/pypoetry/virtualenvs/digital-tekstanalyse-kDjkoATB-py3.10/lib/python3.10/site-packages/jupyter_core/utils/__init__.py", line 165, in wrapped
    return loop.run_until_complete(inner)
  File "/usr/lib/python3.10/asyncio/base_events.py", line 649, in run_until_complete
    return future.result()
  File "/home/larsm/.cache/pypoetry/virtualenvs/digital-tekstanalyse-kDjkoATB-py3.10/lib/python3.10/site-packages/nbclient/client.py", line 709, in async_execute
    await self.async_execute_cell(
  File "/home/larsm/.cache/pypoetry/virtualenvs/digital-tekstanalyse-kDjkoATB-py3.10/lib/python3.10/site-packages/nbclient/client.py", line 1062, in async_execute_cell
    await self._check_raise_for_error(cell, cell_index, exec_reply)
  File "/home/larsm/.cache/pypoetry/virtualenvs/digital-tekstanalyse-kDjkoATB-py3.10/lib/python3.10/site-packages/nbclient/client.py", line 918, in _check_raise_for_error
    raise CellExecutionError.from_cell_and_msg(cell, exec_reply_content)
nbclient.exceptions.CellExecutionError: An error occurred while executing the following cell:
------------------
(coll.frame.counts / tot.freq).sort_values(ascending = False).head(20)
------------------


[0;31m---------------------------------------------------------------------------[0m
[0;31mAttributeError[0m                            Traceback (most recent call last)
[0;32m/tmp/ipykernel_1601493/4223443501.py[0m in [0;36m?[0;34m()[0m
[0;32m----> 1[0;31m [0;34m([0m[0mcoll[0m[0;34m.[0m[0mframe[0m[0;34m.[0m[0mcounts[0m [0;34m/[0m [0mtot[0m[0;34m.[0m[0mfreq[0m[0;34m)[0m[0;34m.[0m[0msort_values[0m[0;34m([0m[0mascending[0m [0;34m=[0m [0;32mFalse[0m[0;34m)[0m[0;34m.[0m[0mhead[0m[0;34m([0m[0;36m20[0m[0;34m)[0m[0;34m[0m[0;34m[0m[0m
[0m
[0;32m~/.cache/pypoetry/virtualenvs/digital-tekstanalyse-kDjkoATB-py3.10/lib/python3.10/site-packages/pandas/core/generic.py[0m in [0;36m?[0;34m(self, name)[0m
[1;32m   6292[0m             [0;32mand[0m [0mname[0m [0;32mnot[0m [0;32min[0m [0mself[0m[0;34m.[0m[0m_accessors[0m[0;34m[0m[0;34m[0m[0m
[1;32m   6293[0m             [0;32mand[0m [0mself[0m[0;34m.[0m[0m_info_axis[0m[0;34m.[0m[0m_can_hold_identifiers_and_holds_name[0m[0;34m([0m[0mname[0m[0;34m)[0m[0;34m[0m[0;34m[0m[0m
[1;32m   6294[0m         ):
[1;32m   6295[0m             [0;32mreturn[0m [0mself[0m[0;34m[[0m[0mname[0m[0;34m][0m[0;34m[0m[0;34m[0m[0m
[0;32m-> 6296[0;31m         [0;32mreturn[0m [0mobject[0m[0;34m.[0m[0m__getattribute__[0m[0;34m([0m[0mself[0m[0;34m,[0m [0mname[0m[0;34m)[0m[0;34m[0m[0;34m[0m[0m
[0m
[0;31mAttributeError[0m: 'DataFrame' object has no attribute 'frame'

